Workbook
Name Slicer_Continent_Region: #N/A
Name Slicer_Year: #N/A

Sheet raw_dataset
A1: Country | B1: Year | C1: Headline Consumer Price Inflation | D1: Energy Consumer Price Inflation | E1: Food Consumer Price Inflation | F1: Official Core Consumer Price Inflation | G1: Producer Price Inflation | H1: GDP deflator Index growth rate | I1: Continent/Region | J1: Score | K1: GDP per Capita | L1: Social support | M1: Healthy life expectancy at birth | N1: Freedom to make life choices | O1: Generosity | P1: Perceptions of corruption
A2: Afghanistan | B2: 2015 | C2: -0.66000003 | D2: -4.25 | E2: -0.83999997 | F2: 0.21999912 | H2: 2.6650903 | I2: South Asia | J2: 3.575 | K2: 0.31982 | L2: 0.30285 | M2: 0.30335 | N2: 0.23414 | O2: 0.3651 | P2: 0.09719
A3: Afghanistan | B3: 2016 | C3: 4.3800001 | D3: 2.0699999 | E3: 5.6700001 | F3: 5.1927602 | H3: -2.4095092 | I3: South Asia | J3: 3.36 | K3: 0.38227 | L3: 0.11037 | M3: 0.17344 | N3: 0.1643 | O3: 0.31268 | P3: 0.07112
A4: Afghanistan | B4: 2017 | C4: 4.976 | D4: 4.4400001 | E4: 6.9400001 | F4: 5.4232275 | H4: 2.404 | I4: South Asia | J4: 3.7939999 | K4: 0.40147722 | L4: 0.58154333 | M4: 0.18074678 | N4: 0.10617952 | O4: 0.31187093 | P4: 0.06115783
A5: Afghanistan | B5: 2018 | C5: 0.63 | D5: 1.4741849 | E5: -1.0459524 | F5: -0.12603251 | H5: 2.0712082 | I5: South Asia | J5: 3.632 | K5: 0.332 | L5: 0.537 | M5: 0.255 | N5: 0.085 | O5: 0.191 | P5: 0.036
A6: Afghanistan | B6: 2019 | C6: 2.302 | D6: -2.4943588 | E6: 3.7947702 | H6: 6.520928 | I6: South Asia | J6: 3.203 | K6: 0.35 | L6: 0.517 | M6: 0.361 | N6: 0 | O6: 0.158 | P6: 0.025
A7: Afghanistan | B7: 2020 | C7: 5.4429998 | E7: 5.8290052 | H7: 5.3071196 | I7: South Asia | J7: 2.5669 | K7: 0.30070585 | L7: 0.35643384 | M7: 0.26605153 | N7: 0 | O7: 0.13523471 | P7: 0.001225785
A8: Afghanistan | B8: 2021 | C8: 5.062 | H8: 0.52451652 | I8: South Asia | J8: 2.523 | K8: 0.37 | L8: 0 | M8: 0.126 | N8: 0 | O8: 0.122 | P8: 0.01
A9: Afghanistan | B9: 2022 | C9: 10.6 | H9: 5.4750714 | I9: South Asia | J9: 2.404 | K9: 0.758 | L9: 0 | M9: 0.289 | N9: 0 | O9: 0.089 | P9: 0.005
A10: Afghanistan | B10: 2023 | I10: South Asia | J10: 1.859 | K10: 0.645 | L10: 0 | M10: 0.087 | N10: 0 | O10: 0.093 | P10: 0.059
A11: Albania | B11: 2015 | C11: 1.9101791 | D11: -0.51999998 | E11: 4.3194895 | F11: -0.15695719 | H11: 0.5642782 | I11: Central and Eastern Europe | J11: 4.959 | K11: 0.87867 | L11: 0.80434 | M11: 0.81325 | N11: 0.35733 | O11: 0.14272 | P11: 0.06413
A12: Albania | B12: 2016 | C12: 1.2912338 | D12: 0.039999999 | E12: 3.2491877 | F12: 0.15138157 | G12: -1.6133035 | H12: -0.63240499 | I12: Central and Eastern Europe | J12: 4.655 | K12: 0.9553 | L12: 0.50163 | M12: 0.73007 | N12: 0.31866 | O12: 0.1684 | P12: 0.05301
A13: Albania | B13: 2017 | C13: 1.987 | D13: 1 | E13: 3.9054298 | F13: 0.819713 | G13: 2.8422458 | H13: 1.4509361 | I13: Central and Eastern Europe | J13: 4.6440001 | K13: 0.99619275 | L13: 0.80368525 | M13: 0.73115975 | N13: 0.38149863 | O13: 0.20131294 | P13: 0.039864216
A14: Albania | B14: 2018 | C14: 2.03 | D14: 2.8 | E14: 2.6714315 | F14: 0.92837429 | G14: 1.602622 | H14: 1.3594644 | I14: Central and Eastern Europe | J14: 4.586 | K14: 0.916 | L14: 0.817 | M14: 0.79 | N14: 0.419 | O14: 0.149 | P14: 0.032
A15: Albania | B15: 2019 | C15: 1.411 | D15: 0.68900985 | E15: 2.911938 | F15: 0.73537815 | G15: -0.79672098 | H15: 0.36341733 | I15: Central and Eastern Europe | J15: 4.719 | K15: 0.947 | L15: 0.848 | M15: 0.874 | N15: 0.383 | O15: 0.178 | P15: 0.027
A16: Albania | B16: 2020 | C16: 1.6208866 | D16: 1.4200893 | E16: 3.6074543 | F16: 1.4114063 | G16: -3.4326388 | H16: 1.4133958 | I16: Central and Eastern Europe | J16: 4.8827 | K16: 0.90665305 | L16: 0.83048391 | M16: 0.84632963 | N16: 0.46194589 | O16: 0.17102776 | P16: 0.025361285
A17: Albania | B17: 2021 | C17: 2.0414716 | D17: 2.7 | E17: 3.9 | F17: 1.6793293 | G17: 2.6989083 | H17: 5.9280138 | I17: Central and Eastern Europe | J17: 5.117 | K17: 1.008 | L17: 0.529 | M17: 0.646 | N17: 0.491 | O17: 0.168 | P17: 0.024
A18: Albania | B18: 2022 | C18: 6.7252027 | D18: 14.216085 | E18: 11.203514 | F18: 6.501041 | G18: 19.937537 | H18: 9.6517633 | I18: Central and Eastern Europe | J18: 5.199 | K18: 1.439 | L18: 0.646 | M18: 0.719 | N18: 0.511 | O18: 0.138 | P18: 0.028
A19: Albania | B19: 2023 | C19: 5.5652239 | D19: -5.0686364 | F19: 5.2225313 | H19: 5.1942693 | I19: Central and Eastern Europe | J19: 5.277 | K19: 1.449 | L19: 0.951 | M19: 0.48 | N19: 0.549 | O19: 0.133 | P19: 0.037
A20: Algeria | B20: 2015 | C20: 4.3916664 | D20: 1.7503198 | E20: 3.604882 | G20: 2.2497056 | H20: -6.4556358 | I20: Middle East and North Africa | J20: 5.605 | K20: 0.93929 | L20: 1.07772 | M20: 0.61766 | N20: 0.28579 | O20: 0.07822 | P20: 0.17383
A21: Algeria | B21: 2016 | C21: 5.8003039 | D21: 5.9810543 | E21: 2.6168447 | G21: 4.1193409 | H21: 1.5487295 | I21: Middle East and North Africa | J21: 6.355 | K21: 1.05266 | L21: 0.83309 | M21: 0.61804 | N21: 0.21006 | O21: 0.07044 | P21: 0.16157
A22: Algeria | B22: 2017 | C22: 5.591 | D22: 2.8017797 | E22: 5.6054001 | G22: 1.8786095 | H22: 6.3908369 | I22: Middle East and North Africa | J22: 5.8720002 | K22: 1.0918645 | L22: 1.1462175 | M22: 0.61758465 | N22: 0.23333581 | O22: 0.069436647 | P22: 0.14609611
A23: Algeria | B23: 2018 | C23: 3.51 | D23: 1.2388263 | E23: 1.7412293 | G23: 4.0810566 | H23: 7.0647866 | I23: Middle East and North Africa | J23: 5.295 | K23: 0.979 | L23: 1.154 | M23: 0.687 | N23: 0.077 | O23: 0.055 | P23: 0.135
A24: Algeria | B24: 2019 | C24: 1.952 | D24: 1.425144 | E24: 0.64319569 | G24: 2.6372888 | H24: -0.90998946 | I24: Middle East and North Africa | J24: 5.211 | K24: 1.002 | L24: 1.16 | M24: 0.785 | N24: 0.086 | O24: 0.073 | P24: 0.114
A25: Algeria | B25: 2020 | C25: 2.4151309 | D25: 1.3897383 | E25: 0.22050305 | H25: -4.6866948 | I25: Middle East and North Africa | J25: 5.0050998 | K25: 0.943856 | L25: 1.1430036 | M25: 0.74541855 | N25: 0.083943799 | O25: 0.11891501 | P25: 0.12919065
A26: Algeria | B26: 2021 | C26: 7.2260631 | D26: 1.47 | E26: 10.13 | G26: 7.4329045 | H26: 15.736744 | I26: Middle East and North Africa | J26: 4.887 | K26: 0.946 | L26: 0.765 | M26: 0.552 | N26: 0.119 | O26: 0.144 | P26: 0.12
A27: Algeria | B27: 2022 | C27: 9.2655155 | D27: 2.4020968 | E27: 12.7019 | H27: 15.567649 | I27: Middle East and North Africa | J27: 5.122 | K27: 1.363 | L27: 0.97 | M27: 0.643 | N27: 0.146 | O27: 0.106 | P27: 0.15
A28: Algeria | B28: 2023 | C28: 9.3221738 | D28: 1.4879778 | E28: 13.256373 | H28: -0.42962924 | I28: Middle East and North Africa | J28: 5.329 | K28: 1.353 | L28: 1.298 | M28: 0.409 | N28: 0.252 | O28: 0.073 | P28: 0.152
A29: Angola | B29: 2015 | C29: 9.1590004 | E29: 9.2964697 | G29: 9.1711226 | H29: -3.5183903 | I29: Sub-Saharan Africa | J29: 4.033 | K29: 0.75778 | L29: 0.8604 | M29: 0.16683 | N29: 0.10384 | O29: 0.12344 | P29: 0.07122
A30: Angola | B30: 2016 | C30: 32.377731 | E30: 21.2355 | G30: 20.392229 | H30: 21.7743 | I30: Sub-Saharan Africa | J30: 3.866 | K30: 0.84731 | L30: 0.66366 | M30: 0.04991 | N30: 0.00589 | O30: 0.12071 | P30: 0.08434
A31: Angola | B31: 2017 | C31: 29.844 | E31: 40.986217 | G31: 23.023481 | H31: 22.617828 | I31: Sub-Saharan Africa | J31: 3.7950001 | K31: 0.85842818 | L31: 1.104412 | M31: 0.049868666 | N31: 0 | O31: 0.09792649 | P31: 0.069720335
A32: Angola | B32: 2018 | C32: 19.63 | E32: 22.350267 | G32: 16.090868 | H32: 33.762011 | I32: Sub-Saharan Africa | J32: 3.795 | K32: 0.73 | L32: 1.125 | M32: 0.269 | N32: 0 | O32: 0.079 | P32: 0.061
A33: Argentina | B33: 2015 | C33: 26.538401 | H33: 26.579992 | I33: Latin America and Caribbean | J33: 6.574 | K33: 1.05351 | L33: 1.24823 | M33: 0.78723 | N33: 0.44974 | O33: 0.11451 | P33: 0.08484
A34: Argentina | B34: 2016 | C34: 39.400002 | E34: 49.432299 | H34: 41.119381 | I34: Latin America and Caribbean | J34: 6.65 | K34: 1.15137 | L34: 1.06612 | M34: 0.69711 | N34: 0.42284 | O34: 0.10989 | P34: 0.07296
A35: Argentina | B35: 2017 | C35: 25.675 | E35: 20.36 | G35: 16.26404 | H35: 26.006378 | I35: Latin America and Caribbean | J35: 6.599 | K35: 1.1852955 | L35: 1.4404511 | M35: 0.69513708 | N35: 0.4945192 | O35: 0.10945706 | P35: 0.059739888
A36: Argentina | B36: 2018 | C36: 34.28 | D36: 52.759998 | E36: 32.738937 | G36: 52.216434 | H36: 40.012154 | I36: Latin America and Caribbean | J36: 6.388 | K36: 1.073 | L36: 1.468 | M36: 0.744 | N36: 0.57 | O36: 0.062 | P36: 0.054
A37: Argentina | B37: 2019 | C37: 53.548 | D37: 49.280769 | E37: 58.344105 | G37: 58.310783 | H37: 50.622581 | I37: Latin America and Caribbean | J37: 6.086 | K37: 1.092 | L37: 1.432 | M37: 0.881 | N37: 0.471 | O37: 0.066 | P37: 0.05
A38: Argentina | B38: 2020 | C38: 42.015095 | D38: 19.946911 | E38: 46.970287 | G38: 42.507 | H38: 39.840848 | I38: Latin America and Caribbean | J38: 5.9747 | K38: 1.0284656 | L38: 1.3725437 | M38: 0.84977371 | N38: 0.52084035 | O38: 0.070100471 | P38: 0.060415059
A39: Argentina | B39: 2021 | C39: 48.40938 | D39: 26.23 | E39: 49.846 | G39: 59.085495 | H39: 54.152412 | I39: Latin America and Caribbean | J39: 5.929 | K39: 1.162 | L39: 0.98 | M39: 0.646 | N39: 0.544 | O39: 0.069 | P39: 0.067
A40: Argentina | B40: 2022 | C40: 72.43076 | D40: 51.398287 | E40: 74.63056 | G40: 60.273346 | H40: 41.066531 | I40: Latin America and Caribbean | J40: 5.967 | K40: 1.592 | L40: 1.102 | M40: 0.662 | N40: 0.555 | O40: 0.081 | P40: 0.085
...

Sheet cleaned_dataset
A1: Country | B1: Year | C1: Headline Consumer Price Inflation | D1: Energy Consumer Price Inflation | E1: Food Consumer Price Inflation | F1: Official Core Consumer Price Inflation | G1: Producer Price Inflation | H1: GDP deflator Index growth rate | I1: Continent/Region | J1: Score | K1: GDP per Capita | L1: Social support | M1: Healthy life expectancy at birth | N1: Freedom to make life choices | O1: Generosity | P1: Perceptions of corruption
A2: Afghanistan | B2: 2015 | C2: -0.66000003 | D2: -4.25 | E2: -0.83999997 | F2: 0.21999912 | G2: 2.73 | H2: 2.6650903 | I2: South Asia | J2: 3.575 | K2: 0.31982 | L2: 0.30285 | M2: 0.30335 | N2: 0.23414 | O2: 0.3651 | P2: 0.09719
A3: Afghanistan | B3: 2016 | C3: 4.3800001 | D3: 2.0699999 | E3: 5.6700001 | F3: 5.1927602 | G3: 2.73 | H3: -2.4095092 | I3: South Asia | J3: 3.36 | K3: 0.38227 | L3: 0.11037 | M3: 0.17344 | N3: 0.1643 | O3: 0.31268 | P3: 0.07112
A4: Afghanistan | B4: 2017 | C4: 4.976 | D4: 4.4400001 | E4: 6.9400001 | F4: 5.4232275 | G4: 2.73 | H4: 2.404 | I4: South Asia | J4: 3.7939999 | K4: 0.40147722 | L4: 0.58154333 | M4: 0.18074678 | N4: 0.10617952 | O4: 0.31187093 | P4: 0.06115783
A5: Afghanistan | B5: 2018 | C5: 0.63 | D5: 1.4741849 | E5: -1.0459524 | F5: -0.12603251 | G5: 2.73 | H5: 2.0712082 | I5: South Asia | J5: 3.632 | K5: 0.332 | L5: 0.537 | M5: 0.255 | N5: 0.085 | O5: 0.191 | P5: 0.036
A6: Afghanistan | B6: 2019 | C6: 2.302 | D6: -2.4943588 | E6: 3.7947702 | F6: 2.25 | G6: 2.73 | H6: 6.520928 | I6: South Asia | J6: 3.203 | K6: 0.35 | L6: 0.517 | M6: 0.361 | N6: 0 | O6: 0.158 | P6: 0.025
A7: Afghanistan | B7: 2020 | C7: 5.4429998 | D7: 2.77 | E7: 5.8290052 | F7: 2.25 | G7: 2.73 | H7: 5.3071196 | I7: South Asia | J7: 2.5669 | K7: 0.30070585 | L7: 0.35643384 | M7: 0.26605153 | N7: 0 | O7: 0.13523471 | P7: 0.001225785
A8: Afghanistan | B8: 2021 | C8: 5.062 | D8: 2.77 | E8: 3.73 | F8: 2.25 | G8: 2.73 | H8: 0.52451652 | I8: South Asia | J8: 2.523 | K8: 0.37 | L8: 0 | M8: 0.126 | N8: 0 | O8: 0.122 | P8: 0.01
A9: Afghanistan | B9: 2022 | C9: 10.6 | D9: 2.77 | E9: 3.73 | F9: 2.25 | G9: 2.73 | H9: 5.4750714 | I9: South Asia | J9: 2.404 | K9: 0.758 | L9: 0 | M9: 0.289 | N9: 0 | O9: 0.089 | P9: 0.005
A10: Afghanistan | B10: 2023 | C10: 3.48 | D10: 2.77 | E10: 3.73 | F10: 2.25 | G10: 2.73 | H10: 3.24 | I10: South Asia | J10: 1.859 | K10: 0.645 | L10: 0 | M10: 0.087 | N10: 0 | O10: 0.093 | P10: 0.059
A11: Albania | B11: 2015 | C11: 1.9101791 | D11: -0.51999998 | E11: 4.3194895 | F11: -0.15695719 | G11: 2.73 | H11: 0.5642782 | I11: Central and Eastern Europe | J11: 4.959 | K11: 0.87867 | L11: 0.80434 | M11: 0.81325 | N11: 0.35733 | O11: 0.14272 | P11: 0.06413
A12: Albania | B12: 2016 | C12: 1.2912338 | D12: 0.039999999 | E12: 3.2491877 | F12: 0.15138157 | G12: -1.6133035 | H12: -0.63240499 | I12: Central and Eastern Europe | J12: 4.655 | K12: 0.9553 | L12: 0.50163 | M12: 0.73007 | N12: 0.31866 | O12: 0.1684 | P12: 0.05301
A13: Albania | B13: 2017 | C13: 1.987 | D13: 1 | E13: 3.9054298 | F13: 0.819713 | G13: 2.8422458 | H13: 1.4509361 | I13: Central and Eastern Europe | J13: 4.6440001 | K13: 0.99619275 | L13: 0.80368525 | M13: 0.73115975 | N13: 0.38149863 | O13: 0.20131294 | P13: 0.039864216
... A1233: Zimbabwe | B1233: 2023 | C1233: 105.40198 | D1233: 115.38065 | E1233: 3.73 | F1233: 2.25 | G1233: 2.73 | H1233: 812.24746 | I1233: Sub-Saharan Africa | J1233: 3.204 | K1233: 0.758 | L1233: 0.881 | M1233: 0.069 | N1233: 0.363 | O1233: 0.112 | P1233: 0.117

Sheet Descriptive_Statistics
A1: Column Name | B1: Description | C1: Column Name | D1: avg | E1: median | F1: missing value % | G1: min | H1: max
A2: Country | B2: Each Country Name | C2: C | D2: =AVERAGE(cleaned_dataset!C:C) -> 7.2937453 | E2: =MEDIAN(cleaned_dataset!C:C) -> 3.48 | F2: =32/1232*100 -> 2.5974026 | G2: =MIN(cleaned_dataset!C:C) -> -3.752996 | H2: =MAX(cleaned_dataset!C:C) -> 557.21
A3: Year | B3: 2015 to 2023 data of each country | C3: D | D3: =AVERAGE(cleaned_dataset!D:D) -> 6.0030468 | E3: =MEDIAN(cleaned_dataset!D:D) -> 2.77 | F3: =142/1232*100 -> 11.525974 | G3: =MIN(cleaned_dataset!D:D) -> -23.879999 | H3: =MAX(cleaned_dataset!D:D) -> 306.43167
A4: Headline Consumer Price Inflation | B4: year wise inflation in headline | C4: E | D4: =AVERAGE(cleaned_dataset!E:E) -> 7.6740797 | E4: =MEDIAN(cleaned_dataset!E:E) -> 3.73 | F4: =102/1232*100 -> 8.2792208 | G4: =MIN(cleaned_dataset!E:E) -> -22.030001 | H4: =MAX(cleaned_dataset!E:E) -> 601.02024
A5: Energy Consumer Price Inflation | B5: year wise price inflation in energy consumption | C5: F | D5: =AVERAGE(cleaned_dataset!F:F) -> 3.0022379 | E5: =MEDIAN(cleaned_dataset!F:F) -> 2.25 | F5: =498/1232*100 -> 40.422078 | G5: =MIN(cleaned_dataset!F:F) -> -28.619415 | H5: =MAX(cleaned_dataset!F:F) -> 58.851863
A6: Food Consumer Price Inflation | B6: year wise price inflation in food consumption | C6: G | D6: =AVERAGE(cleaned_dataset!G:G) -> 4.6724034 | E6: =MEDIAN(cleaned_dataset!G:G) -> 2.73 | F6: =463/1232*100 -> 37.581169 | G6: =MIN(cleaned_dataset!G:G) -> -83.339781 | H6: =MAX(cleaned_dataset!G:G) -> 128.47664
A7: Official Core Consumer Price Inflation | B7: Year-wise core consumer price inflation | C7: H | D7: =AVERAGE(cleaned_dataset!H:H) -> 7.004731 | E7: =MEDIAN(cleaned_dataset!H:H) -> 3.24 | F7: =21/1232*100 -> 1.7045455 | G7: =MIN(cleaned_dataset!H:H) -> -26.1 | H7: =MAX(cleaned_dataset!H:H) -> 812.24746
A8: Producer Price Inflation | B8: year wise inflation in producer price | C8: J | D8: =AVERAGE(cleaned_dataset!J:J) -> 5.4990006 | E8: =MEDIAN(cleaned_dataset!J:J) -> 5.5389499 | F8: 0 | G8: =MIN(cleaned_dataset!J:J) -> 1.859 | H8: =MAX(cleaned_dataset!J:J) -> 7.842
A9: GDP deflator Index growth rate | B9: year wise index growth rate of gdp deflator | C9: K | D9: =AVERAGE(cleaned_dataset!K:K) -> 1.0307665 | E9: =MEDIAN(cleaned_dataset!K:K) -> 1.0515 | F9: 0 | G9: =MIN(cleaned_dataset!K:K) -> 0 | H9: =MAX(cleaned_dataset!K:K) -> 2.209
A10: Continent/Region | B10: Each region/continent name | C10: L | D10: =AVERAGE(cleaned_dataset!L:L) -> 1.0566232 | E10: =MEDIAN(cleaned_dataset!L:L) -> 1.0935 | F10: 0 | G10: =MIN(cleaned_dataset!L:L) -> 0 | H10: =MAX(cleaned_dataset!L:L) -> 1.644
A11: Score | B11: Overall happiness score of each country. | C11: M | D11: =AVERAGE(cleaned_dataset!M:M) -> 0.58875477 | E11: =MEDIAN(cleaned_dataset!M:M) -> 0.61783 | F11: 0 | G11: =MIN(cleaned_dataset!M:M) -> 0 | H11: =MAX(cleaned_dataset!M:M) -> 1.141
A12: GDP per Capita | B12: year wise gdp per capita growth | C12: N | D12: =AVERAGE(cleaned_dataset!N:N) -> 0.45939301 | E12: =MEDIAN(cleaned_dataset!N:N) -> 0.481 | F12: 0 | G12: =MIN(cleaned_dataset!N:N) -> 0 | H12: =MAX(cleaned_dataset!N:N) -> 0.772
A13: Social support | B13: year wise measure of social support | C13: O | D13: =AVERAGE(cleaned_dataset!O:O) -> 0.1961449 | E13: =MEDIAN(cleaned_dataset!O:O) -> 0.183 | F13: 0 | G13: =MIN(cleaned_dataset!O:O) -> 0 | H13: =MAX(cleaned_dataset!O:O) -> 0.83807516
A14: Healthy life expectancy at birth | B14: year wise expectancy of healthy life | C14: P | D14: =AVERAGE(cleaned_dataset!P:P) -> 0.13342698 | E14: =MEDIAN(cleaned_dataset!P:P) -> 0.09818015 | F14: =1/1232*100 -> 0.081168831 | G14: =MIN(cleaned_dataset!P:P) -> 0 | H14: =MAX(cleaned_dataset!P:P) -> 0.587
A15: Freedom to make life choices | B15: year wise measure of freedom to make life choices
A16: Generosity | B16: Year-wise measure of the generosity in each country
A17: Perceptions of corruption | B17: year wise measure of the perceptions of corruption

Sheet Median Imputation
A1: Column Name | B1: Missing % | C1: Action
A2: Country | B2: 0 | C2: No Action
A3: Year | B3: 0 | C3: No Action
A4: Headline Consumer Price Inflation | B4: 0.026 | C4: Median Imputation
A5: Energy Consumer Price Inflation | B5: 0.1153 | C5: Median Imputation
A6: Food Consumer Price Inflation | B6: 0.0828 | C6: Median Imputation
A7: Official Core Consumer Price Inflation | B7: 0.4042 | C7: Median Imputation
A8: Producer Price Inflation | B8: 0.3758 | C8: Median Imputation
A9: GDP deflator Index growth rate | B9: 0.017 | C9: Median Imputation
A10: Continent/Region | B10: 0 | C10: No Action
A11: Score | B11: 0 | C11: No Action
A12: GDP per Capita | B12: 0 | C12: No Action
A13: Social support | B13: 0 | C13: No Action
... A17: Perceptions of corruption | B17: 0.0008 | C17: Median Imputation

Sheet Relationship Analysis

Sheet Pivot_Table
B2: Row Labels | C2: Average of Score | E2: Row Labels | F2: Average of GDP per Capita | H2: Row Labels | I2: Average of Headline Consumer Price Inflation
B3: North America and ANZ | C3: 7.1760583 | E3: North America and ANZ | F3: 1.5018248 | H3: Sub-Saharan Africa | I3: 13.037569
B4: Western Europe | C4: 6.8502203 | E4: Western Europe | F4: 1.4941314 | H4: Middle East and North Africa | I4: 9.574058
B5: Latin America and Caribbean | C5: 6.0281508 | E5: East Asia | F5: 1.2747018 | H5: Commonwealth of Independent States | I5: 9.1667209
B6: East Asia | C6: 5.7644805 | E6: Middle East and North Africa | F6: 1.2646163 | H6: Latin America and Caribbean | I6: 7.0424024
B7: Commonwealth of Independent States | C7: 5.6946371 | E7: Central and Eastern Europe | F7: 1.1785998 | H7: South Asia | I7: 6.5607303
B8: Middle East and North Africa | C8: 5.6265808 | E8: Southeast Asia | F8: 1.0349521 | H8: Central and Eastern Europe | I8: 4.8358675
B9: Central and Eastern Europe | C9: 5.5687202 | E9: Latin America and Caribbean | F9: 1.0293293 | H9: Southeast Asia | I9: 3.4178314
B10: Southeast Asia | C10: 5.4207458 | E10: Commonwealth of Independent States | F10: 0.94958152 | H10: East Asia | I10: 3.2563387
B11: South Asia | C11: 4.4732639 | E11: South Asia | F11: 0.73281297 | H11: North America and ANZ | I11: 2.7138349
B12: Sub-Saharan Africa | C12: 4.2580359 | E12: Sub-Saharan Africa | F12: 0.54982253 | H12: Western Europe | I12: 2.2478307
B13: Grand Total | C13: 5.4990006 | E13: Grand Total | F13: 1.0307665 | H13: Grand Total | I13: 7.2937453
B15: Row Labels | C15: Average of GDP per Capita | D15: Average of Headline Consumer Price Inflation | E15: Average of Score | G15: Row Labels | H15: Average of GDP per Capita | I15: Average of Headline Consumer Price Inflation | J15: Average of Score
B16: Central and Eastern Europe | C16: 1.1785998 | D16: 4.8358675 | E16: 5.5687202 | G16: 2015 | H16: 0.85614592 | I16: 3.6545623 | J16: 5.434007
B17: Commonwealth of Independent States | C17: 0.94958152 | D17: 9.1667209 | E17: 5.6946371 | G17: 2016 | H17: 0.96641156 | I17: 6.9875816 | J17: 5.4449291
B18: East Asia | C18: 1.2747018 | D18: 3.2563387 | E18: 5.7644805 | G18: 2017 | H18: 0.98999185 | I18: 5.9758036 | J18: 5.408
B19: Latin America and Caribbean | C19: 1.0293293 | D19: 7.0424024 | E19: 6.0281508 | G19: 2018 | H19: 0.90133099 | I19: 4.97999 | J19: 5.4423028
B20: Middle East and North Africa | C20: 1.2646163 | D20: 9.574058 | E20: 5.6265808 | G20: 2019 | H20: 0.92046809 | I20: 5.731039 | J20: 5.4810496
B21: North America and ANZ | C21: 1.5018248 | D21: 2.7138349 | E21: 7.1760583 | G21: 2020 | H21: 0.8810635 | I21: 8.4672968 | J21: 5.5294551
B22: South Asia | C22: 0.73281297 | D22: 6.5607303 | E22: 4.4732639 | G22: 2021 | H22: 0.98676296 | I22: 6.8840217 | J22: 5.5815852
B23: Southeast Asia | C23: 1.0349521 | D23: 3.4178314 | E23: 5.4207458 | G23: 2022 | H23: 1.4288769 | I23: 12.825812 | J23: 5.5999769
B24: Sub-Saharan Africa | C24: 0.54982253 | D24: 13.037569 | E24: 4.2580359 | G24: 2023 | H24: 1.427459 | I24: 11.136791 | J24: 5.595623
B25: Western Europe | C25: 1.4941314 | D25: 2.2478307 | E25: 6.8502203 | G25: Grand Total | H25: 1.0307665 | I25: 7.2937453 | J25: 5.4990006
B26: Grand Total | C26: 1.0307665 | D26: 7.2937453 | E26: 5.4990006
A30: Average of Score | B30: Column Labels
A31: Row Labels | B31: Central and Eastern Europe | C31: Commonwealth of Independent States | D31: East Asia | E31: Latin America and Caribbean | F31: Middle East and North Africa | G31: North America and ANZ | H31: South Asia | I31: Southeast Asia | J31: Sub-Saharan Africa | K31: Western Europe | L31: Grand Total
A32: 2015 | B32: 5.280913 | C32: 5.548 | D32: 5.57475 | E32: 6.113 | F32: 5.8306667 | G32: 7.279 | H32: 4.5808571 | I32: 5.372625 | J32: 4.1915 | K32: 6.73935 | L32: 5.434007
A33: 2016 | B33: 5.3108261 | C33: 5.64 | D33: 5.613 | E33: 6.1025217 | F33: 5.8295 | G33: 7.28875 | H33: 4.5632857 | I33: 5.39675 | J33: 4.1089118 | K33: 6.7314 | L33: 5.4449291
A34: 2017 | B34: 5.3594783 | C34: 5.66325 | D34: 5.6424999 | E34: 5.9915238 | F34: 5.7690714 | G34: 7.22675 | H34: 4.6284286 | I34: 5.444875 | J34: 4.1004167 | K34: 6.7484 | L34: 5.408
A35: 2018 | B35: 5.4257826 | C35: 5.68025 | D35: 5.68175 | E35: 6.004619 | F35: 5.6918571 | G35: 7.2025 | H35: 4.6038571 | I35: 5.39975 | J35: 4.1703056 | K35: 6.7817619 | L35: 5.4423028
A36: 2019 | B36: 5.5512174 | C36: 5.67425 | D36: 5.702 | E36: 6.0168 | F36: 5.6607857 | G36: 7.17625 | H36: 4.5268571 | I36: 5.333375 | J36: 4.2586667 | K36: 6.8421905 | L36: 5.4810496
A37: 2020 | B37: 5.6629217 | C37: 5.7475749 | D37: 5.726575 | E37: 6.028215 | F37: 5.5352077 | G37: 7.173525 | H37: 4.4754428 | I37: 5.4452125 | J37: 4.3276286 | K37: 6.967405 | L37: 5.5294551
A38: 2021 | B38: 5.7939565 | C38: 5.71575 | D38: 5.885 | E38: 5.9615263 | F38: 5.5043846 | G38: 7.1285 | H38: 4.4418571 | I38: 5.45475 | J38: 4.4273333 | K38: 6.98385 | L38: 5.5815852
A39: 2022 | B39: 5.8555909 | C39: 5.787 | D39: 5.97425 | E39: 6.0073333 | F39: 5.3873846 | G39: 7.091 | H39: 4.2651667 | I39: 5.468125 | J39: 4.4167419 | K39: 6.9671 | L39: 5.5999769
A40: 2023 | B40: 5.9385 | C40: 5.8293333 | D40: 6.0805 | E40: 6.008 | F40: 5.2862 | G40: 7.01825 | H40: 4.089 | I40: 5.47125 | J40: 4.3729655 | K40: 6.89435 | L40: 5.595623
A41: Grand Total | B41: 5.5687202 | C41: 5.6946371 | D41: 5.7644805 | E41: 6.0281508 | F41: 5.6265808 | G41: 7.1760583 | H41: 4.4732639 | I41: 5.4207458 | J41: 4.2580359 | K41: 6.8502203 | L41: 5.4990006
D43: Row Labels | E43: Average of Score | G43: Row Labels | H43: Average of Score
D44: Finland | E44: 7.6627444 | G44: Afghanistan | H44: 2.9907667
D45: Denmark | E45: 7.5797333 | G45: Central African Republic | H45: 3.20258
D46: Iceland | E46: 7.5222778 | G46: South Sudan | H46: 3.26932
...

Sheet Pivot_Table_2
B1: Average_Happiness | D1: Average_GDP | F1: Average_Inflation | H1: Total_Countries
B2: 5.4990006 | D2: 1.0307665 | F2: 7.2937453 | H2: 148
B4: Row Labels | C4: Average of Score
B5: 2015 | C5: 5.434007
B6: 2016 | C6: 5.4449291
B7: 2017 | C7: 5.408
B8: 2018 | C8: 5.4423028
B9: 2019 | C9: 5.4810496
B10: 2020 | C10: 5.5294551
B11: 2021 | C11: 5.5815852
B12: 2022 | C12: 5.5999769
B13: 2023 | C13: 5.595623
B14: Grand Total | C14: 5.4990006

Sheet Dashboard
C1: Global Happiness Dashboard
C3: Average_Happiness_Score | E3: Average_GDP_per_Capita | G3: Average_Inflation | I3: Total_Countries
C4: 5.4990006 | E4: 1.0307665 | G4: 7.2937453 | I4: 148

Sheet Insights
A1: Insights
A2: 1: North America and ANZ has the highest average happiness score (7.18), while Sub-Saharan Africa has the lowest (4.26).
A3: This highlights a clear regional difference in happiness levels.
A5: 2: Finland has the highest average happiness score, while Afghanistan has the lowest average happiness score in the dataset.
A7: 3: Global happiness remained relatively stable between 2015 and 2023, with only gradual changes over time, as shown in the line chart.
A9: 4: The scatter plot shows a positive relationship between GDP per Capita and Happiness Score, meaning countries with
A10: higher GDP per Capita generally tend to have higher happiness scores.
A12: 5: The dashboard an average happiness score of approximately 5.50 and an average GDP per Capita of approximately 1.03.

Sheet Recommendations
A1: Recommendations
A2: 1: Countries with lower happiness scores should study the economic and social policies adopted by the top-performing countries
A3: to identify practices that could improve overall well-being.
A5: 2: Governments should promote sustainable economic growth and employment opportunities, as the analysis indicates that
A6: countries with higher GDP per Capita generally report higher happiness levels.
A8: 3: Regions with consistently lower happiness scores should be prioritized for targeted economic and social development initiatives,
A9: while monitoring changes over time to evaluate progress.
A11: 4: Governments should continuously monitor happiness and economic indicators over time to assess the
A12: effectiveness of public policies and identify long-term trends.
A14: 5: Policymakers should benchmark the performance of the top 10 happiest countries to understand which measurable economic and
A15: governance factors contribute to higher well-being.
